Workbook
Name lDiocesis: Parámetros!$A$2:$A$46
Name lNComunidad: Parámetros!$E$2:$E$31
Name lPasos: Parámetros!$C$2:$C$18

Sheet Registrar aquí
A1: CENTRO NEOCATECUMENAL ARQUIDIOCESANO - LIMA Psje. Los Camaroneros 499 - Rímac Telf. 481 6668 - 482 4053
B2: DATOS GENERALES
B4: Por favor, registra la información solicitada.
B6: INFORMACIÓN GENERAL
B8: ¿Es parroquia o capilla? | C8: Parroquia | D8: ç Haga click aquí para seleccionar.
B9: ¿De qué parroquia depende?
B11: ="DE LA "&UPPER(C8) -> DE LA PARROQUIA
B12: ="Nombre de la "&C8 -> Nombre de la Parroquia
B15: DE LA COMUNIDAD
B16: Número de comunidad | D16: ç Haga click aquí para seleccionar.
B17: Fecha de nacimiento de la comunidad
B18: Catequizados por (N° comunidad y parroquia)
B19: Nombre del catequista
B21: Número de hermanos | C21: =SUM(C22*2,C23,C24,C25) -> 0
B22: Matrimonios
B23: Hombres
B24: Mujeres
B25: Presbíteros
B27: N° aproximado de hnos. que caminan:
B29: Último paso | D29: ç Haga click aquí para seleccionar el paso.
B30: Fecha del paso
B31: ¿Hubo rito? | D31: ç Haga click aquí para seleccionar.
B33: Nombres y apellidos | C33: Domicilio | D33: Teléfono fijo | E33: Celular
B34: RESPONSABLE
C36: Correo electrónico:
B37: VICE-RESPONSABLE
C39: Correo electrónico:
B40: PRESBÍTEROS DE LA COMUNIDAD
B46: CORRESPONSABLES
B52: 1er. EQUIPO DE CATEQUISTAS (En caso de tenerlo)
C54: Correo electrónico
B60: 2do. EQUIPO DE CATEQUISTAS (En caso de tenerlo)
C62: Correo electrónico
B68: 3er. EQUIPO DE CATEQUISTAS (En caso de tenerlo)
C70: Correo electrónico
B76: 4to. EQUIPO DE CATEQUISTAS (En caso de tenerlo)
C78: Correo electrónico
C85: Total de hnos. que conforman los equipos catequistas
B87: CARISMAS
B88: ITINERANTES
...

Sheet Hoja para Impresión
A1: CENTRO NEOCATECUMENAL ARQUIDIOCESANO - LIMA Psje. Los Camaroneros 499 - Rímac Telf. 481 6668 - 482 4053
B3: =UPPER('Registrar aquí'!C8) -> PARROQUIA
B4: =IF('Registrar aquí'!C8="Parroquia","Nombre: "&'Registrar aquí'!C12,"Capilla: "&'Registrar aquí'!C12&" (Depende de la parroquia "&'Registrar aquí'!C9&")") -> Nombre:
B6: DE LA COMUNIDAD
B7: Nº de COMUNIDAD | C7: =VLOOKUP('Registrar aquí'!C16,Parámetros!E2:$G$26,3,FALSE) -> #N/A
B9: Nº de HERMANOS | C9: ='Registrar aquí'!C21 -> 0
B10: Matrimonios | C10: ='Registrar aquí'!C22 -> 0
B11: Hombres | C11: ='Registrar aquí'!C23 -> 0
B12: Mujeres | C12: ='Registrar aquí'!C24 -> 0
B13: Presbíteros | C13: ='Registrar aquí'!C25 -> 0
B15: Catequizados por | C15: ='Registrar aquí'!C18&"."&'Registrar aquí'!C19 -> .
B16: Fecha de nacimiento de la comunidad | C16: ='Registrar aquí'!C17 -> 0
B17: Paso | C17: ='Registrar aquí'!C29 -> 0
B18: Fecha del paso | C18: =TEXT('Registrar aquí'!C30,"dd/mm/yyyy")&". "&IF('Registrar aquí'!C31="Si","Hubo rito.","No hubo rito.") -> 00/01/1900. No hubo rito.
B20: EQUIPO CATEQUISTA/RESPONSABLE
B21: Nombres y apellidos | C21: Domicilio | D21: Teléfono fijo | E21: Teléfono móvil
B22: RESPONSABLE
B23: =IF(ISBLANK('Registrar aquí'!B35),"",'Registrar aquí'!B35) | C23: =IF(ISBLANK('Registrar aquí'!C35),"",'Registrar aquí'!C35) | D23: =IF(ISBLANK('Registrar aquí'!D35),"",'Registrar aquí'!D35) | E23: =IF(ISBLANK('Registrar aquí'!E35),"",'Registrar aquí'!E35)
C24: Correo electrónico | D24: =IF(ISBLANK('Registrar aquí'!D36),"",'Registrar aquí'!D36)
B25: VICE-RESPONSABLE
B26: =IF(ISBLANK('Registrar aquí'!B38),"",'Registrar aquí'!B38) | C26: =IF(ISBLANK('Registrar aquí'!C38),"",'Registrar aquí'!C38) | D26: =IF(ISBLANK('Registrar aquí'!D38),"",'Registrar aquí'!D38) | E26: =IF(ISBLANK('Registrar aquí'!E38),"",'Registrar aquí'!E38)
C27: Correo electrónico | D27: =IF(ISBLANK('Registrar aquí'!D39),"",'Registrar aquí'!D39)
B28: PRESBÍTEROS DE LA COMUNIDAD
B29: =IF(ISBLANK('Registrar aquí'!B41),"",'Registrar aquí'!B41) | C29: =IF(ISBLANK('Registrar aquí'!C41),"",'Registrar aquí'!C41) | D29: =IF(ISBLANK('Registrar aquí'!D41),"",'Registrar aquí'!D41) | E29: =IF(ISBLANK('Registrar aquí'!E41),"",'Registrar aquí'!E41)
B30: =IF(ISBLANK('Registrar aquí'!B42),"",'Registrar aquí'!B42) | C30: =IF(ISBLANK('Registrar aquí'!C42),"",'Registrar aquí'!C42) | D30: =IF(ISBLANK('Registrar aquí'!D42),"",'Registrar aquí'!D42) | E30: =IF(ISBLANK('Registrar aquí'!E42),"",'Registrar aquí'!E42)
B31: =IF(ISBLANK('Registrar aquí'!B43),"",'Registrar aquí'!B43) | C31: =IF(ISBLANK('Registrar aquí'!C43),"",'Registrar aquí'!C43) | D31: =IF(ISBLANK('Registrar aquí'!D43),"",'Registrar aquí'!D43) | E31: =IF(ISBLANK('Registrar aquí'!E43),"",'Registrar aquí'!E43)
B32: =IF(ISBLANK('Registrar aquí'!B44),"",'Registrar aquí'!B44) | C32: =IF(ISBLANK('Registrar aquí'!C44),"",'Registrar aquí'!C44) | D32: =IF(ISBLANK('Registrar aquí'!D44),"",'Registrar aquí'!D44) | E32: =IF(ISBLANK('Registrar aquí'!E44),"",'Registrar aquí'!E44)
B33: =IF(ISBLANK('Registrar aquí'!B45),"",'Registrar aquí'!B45) | C33: =IF(ISBLANK('Registrar aquí'!C45),"",'Registrar aquí'!C45) | D33: =IF(ISBLANK('Registrar aquí'!D45),"",'Registrar aquí'!D45) | E33: =IF(ISBLANK('Registrar aquí'!E45),"",'Registrar aquí'!E45)
B34: CORRESPONSABLES
B35: =IF(ISBLANK('Registrar aquí'!B47),"",'Registrar aquí'!B47) | C35: =IF(ISBLANK('Registrar aquí'!C47),"",'Registrar aquí'!C47) | D35: =IF(ISBLANK('Registrar aquí'!D47),"",'Registrar aquí'!D47) | E35: =IF(ISBLANK('Registrar aquí'!E47),"",'Registrar aquí'!E47)
B36: =IF(ISBLANK('Registrar aquí'!B48),"",'Registrar aquí'!B48) | C36: =IF(ISBLANK('Registrar aquí'!C48),"",'Registrar aquí'!C48) | D36: =IF(ISBLANK('Registrar aquí'!D48),"",'Registrar aquí'!D48) | E36: =IF(ISBLANK('Registrar aquí'!E48),"",'Registrar aquí'!E48)
B37: =IF(ISBLANK('Registrar aquí'!B49),"",'Registrar aquí'!B49) | C37: =IF(ISBLANK('Registrar aquí'!C49),"",'Registrar aquí'!C49) | D37: =IF(ISBLANK('Registrar aquí'!D49),"",'Registrar aquí'!D49) | E37: =IF(ISBLANK('Registrar aquí'!E49),"",'Registrar aquí'!E49)
B38: =IF(ISBLANK('Registrar aquí'!B50),"",'Registrar aquí'!B50) | C38: =IF(ISBLANK('Registrar aquí'!C50),"",'Registrar aquí'!C50) | D38: =IF(ISBLANK('Registrar aquí'!D50),"",'Registrar aquí'!D50) | E38: =IF(ISBLANK('Registrar aquí'!E50),"",'Registrar aquí'!E50)
B39: =IF(ISBLANK('Registrar aquí'!B51),"",'Registrar aquí'!B51) | C39: =IF(ISBLANK('Registrar aquí'!C51),"",'Registrar aquí'!C51) | D39: =IF(ISBLANK('Registrar aquí'!D51),"",'Registrar aquí'!D51) | E39: =IF(ISBLANK('Registrar aquí'!E51),"",'Registrar aquí'!E51)
B40: 1er. EQUIPO DE CATEQUISTAS (En caso de tenerlo)
B41: =IF(ISBLANK('Registrar aquí'!B53),"",'Registrar aquí'!B53) | C41: =IF(ISBLANK('Registrar aquí'!C53),"",'Registrar aquí'!C53) | D41: =IF(ISBLANK('Registrar aquí'!D53),"",'Registrar aquí'!D53) | E41: =IF(ISBLANK('Registrar aquí'!E53),"",'Registrar aquí'!E53)
C42: Correo electrónico | D42: =IF(ISBLANK('Registrar aquí'!D54),"",'Registrar aquí'!D54)
B43: =IF(ISBLANK('Registrar aquí'!B55),"",'Registrar aquí'!B55) | C43: =IF(ISBLANK('Registrar aquí'!C55),"",'Registrar aquí'!C55) | D43: =IF(ISBLANK('Registrar aquí'!D55),"",'Registrar aquí'!D55) | E43: =IF(ISBLANK('Registrar aquí'!E55),"",'Registrar aquí'!E55)
B44: =IF(ISBLANK('Registrar aquí'!B56),"",'Registrar aquí'!B56) | C44: =IF(ISBLANK('Registrar aquí'!C56),"",'Registrar aquí'!C56) | D44: =IF(ISBLANK('Registrar aquí'!D56),"",'Registrar aquí'!D56) | E44: =IF(ISBLANK('Registrar aquí'!E56),"",'Registrar aquí'!E56)
B45: =IF(ISBLANK('Registrar aquí'!#REF!),"",'Registrar aquí'!#REF!) -> #REF! | C45: =IF(ISBLANK('Registrar aquí'!#REF!),"",'Registrar aquí'!#REF!) -> #REF! | D45: =IF(ISBLANK('Registrar aquí'!#REF!),"",'Registrar aquí'!#REF!) -> #REF! | E45: =IF(ISBLANK('Registrar aquí'!#REF!),"",'Registrar aquí'!#REF!) -> #REF!
...

Sheet Parámetros
A1: Diócesis | C1: Pasos | E1: Comunidad
A2: Arquidiócesis de Arequipa | C2: Convivencia de Inicio | E2: Primera | F2: 1 | G2: 1ra
A3: Arquidiócesis de Ayacucho | C3: Convivencia de Año | E3: Segunda | F3: 2 | G3: 2da
A4: Arquidiócesis de Cuzco | C4: I Escrutinio | E4: Tercera | F4: 3 | G4: 3ra
A5: Arquidiócesis de Huancayo | C5: Shema | E5: Cuarta | F5: 4 | G5: 4ta
A6: Arquidiócesis de Lima | C6: II Escrutinio | E6: Quinta | F6: 5 | G6: 5ta
A7: Arquidiócesis de Piura | C7: Iniciación a la Oración | E7: Sexta | F7: 6 | G7: 6ta
A8: Arquidiócesis de Trujillo | C8: Traditio | E8: Séptima | F8: 7 | G8: 7ma
A9: Diócesis de Abancay | C9: Re-traditio | E9: Octava | F9: 8 | G9: 8va
A10: Diócesis de Cajamarca | C10: Redditio | E10: Novena | F10: 9 | G10: 9na
A11: Diócesis de Callao | C11: I Padre Nuestro | E11: Décima | F11: 10 | G11: 10ma
A12: Diócesis de Carabayllo | C12: II Padre Nuestro | E12: Undécima | F12: 11 | G12: 11ma
A13: Diócesis de Chachapoyas | C13: III Padre Nuestro | E13: Duodécima | F13: 12 | G13: 12ma
... A18: Diócesis de Huacho | C18: Matrimonio espiritual | E18: Décimo séptima | F18: 17 | G18: 17ma
A19: Diócesis de Huancavélica | E19: Décimo octava | F19: 18 | G19: 18va
A20: Diócesis de Huánuco | E20: Décimo novena | F20: 19 | G20: 19na
A21: Diócesis de Huaraz | E21: Vigésima | F21: 20 | G21: 20ma
A22: Diócesis de Huarí | E22: Vigésimo primera | F22: 21 | G22: 21ra
A23: Diócesis de Ica | E23: Vigésimo segunda | F23: 22 | G23: 22da
A24: Diócesis de Lurín | E24: Vigésimo tercera | F24: 23 | G24: 23ra
A25: Diócesis de Puno | E25: Vigésimo cuarta | F25: 24 | G25: 24ta
A26: Diócesis de Tacna y Moquegua | E26: Vigésimo quinta | F26: 25 | G26: 25ta
A27: Diócesis de Tarma | E27: Vigésimo sexta | F27: 26 | G27: 26ta
A28: Obispado castrense | E28: Vigésimo séptima | F28: 27 | G28: 27ma
A29: Prelatura de Ayaviri | E29: Vigésimo octava | F29: 28 | G29: 28va
A30: Prelatura de Caravelí | E30: Vigésimo novena | F30: 29 | G30: 29na
A31: Prelatura de Chota | E31: Trigésima | F31: 30 | G31: 30ma
A32: Prelatura de Chuquibamba
A33: Prelatura de Chuquibambilla
A34: Prelatura de Huamachuco
A35: Prelatura de Juli
A36: Prelatura de Moyobamba
A37: Prelatura de Sicuani
A38: Prelatura de Yauyos
A39: Vicariato apostólico de Iquitos
A40: Vicariato apostólico de Jaén en Peru o San Francisco Javier
A41: Vicariato apostólico de Pucallpa
A42: Vicariato apostólico de Puerto Maldonado
A43: Vicariato apostólico de Requena
... A46: Vicariato apostólico de Yurimaguas
